<?xml version="1.0"?>
<robot name="rover" xmlns:xacro="http://wiki.ros.org/xacro">

  <xacro:macro name="rover_wheel"  params="parent">

    <joint name="left_back_sop_link_joint" type="fixed">
        <origin rpy="0.00000 0.00000 -0.00000" xyz="-1.00000 0.75000 -0.10000"/>
        <parent link="base_link"/>
        <child link="left_back_sop_link"/>
    </joint>

    <joint name="left_back_wheel_link_joint" type="continuous">
        <limit lower="0" upper="0" effort="1000.00000" velocity="100.00000"/>
        <origin rpy="1.57080 0.00000 -3.14159" xyz="-0.00000 0.15000 0.00000"/>
        <parent link="left_back_sop_link"/>
        <child link="left_back_wheel_link"/>
        <axis xyz="0.00000 0.00000 1.00000"/>
    </joint>

    <joint name="left_front_sop_link_joint" type="fixed">
        <origin rpy="0.00000 0.00000 -0.00000" xyz="1.00000 0.75000 -0.10000"/>
        <parent link="base_link"/>
        <child link="left_front_sop_link"/>
    </joint>

    <joint name="left_front_wheel_link_joint" type="continuous">
        <limit lower="0" upper="0" effort="1000.00000" velocity="100.00000"/>
        <origin rpy="1.57080 0.00000 -3.14159" xyz="-0.00000 0.15000 0.00000"/>
        <parent link="left_front_sop_link"/>
        <child link="left_front_wheel_link"/>
        <axis xyz="0.00000 0.00000 1.00000"/>
    </joint>

    <joint name="right_back_sop_link_joint" type="fixed">
        <origin rpy="0.00000 0.00000 -0.00000" xyz="-1.00000 -0.75000 -0.10000"/>
        <parent link="base_link"/>
        <child link="right_back_sop_link"/>
    </joint>

    <joint name="right_back_wheel_link_joint" type="continuous">
        <limit lower="0" upper="0" effort="1000.00000" velocity="100.00000"/>
        <origin rpy="-1.57080 3.14159 3.14159" xyz="0.00000 -0.15000 -0.00000"/>
        <parent link="right_back_sop_link"/>
        <child link="right_back_wheel_link"/>
        <axis xyz="0.00000 0.00000 1.00000"/>
    </joint>

    <joint name="right_front_sop_link_joint" type="fixed">
        <origin rpy="0.00000 0.00000 -0.00000" xyz="1.00000 -0.75000 -0.10000"/>
        <parent link="base_link"/>
        <child link="right_front_sop_link"/>
    </joint>

    <joint name="right_front_wheel_link_joint" type="continuous">
        <limit lower="0" upper="0" effort="1000.00000" velocity="100.00000"/>
        <origin rpy="-1.57080 3.14159 3.14159" xyz="0.00000 -0.15000 -0.00000"/>
        <parent link="right_front_sop_link"/>
        <child link="right_front_wheel_link"/>
        <axis xyz="0.00000 0.00000 1.00000"/>
    </joint>

    <link name="left_back_sop_link">
        <collision name="left_back_sop_collision">
        <origin rpy="0.00000 0.00000 -0.00000" xyz="0.00000 0.00000 -0.00000"/>
        <geometry>
            <box size="0.60000 0.30000 0.60000"/>
        </geometry>
        </collision>
        <inertial>
        <inertia ixx="0.18750" ixy="0.00000" ixz="0.00000" iyy="0.30000" iyz="0.00000" izz="0.18750"/>
        <origin rpy="0.00000 0.00000 0.00000" xyz="-0.00000 0.00000 -0.00000"/>
        <mass value="5.00000"/>
        </inertial>
        <visual name="left_back_sop">
        <origin rpy="0.00000 0.00000 -0.00000" xyz="0.00000 0.00000 -0.00000"/>
        <material name="turnarrow.004"/>
        <geometry>
            <box size="0.60000 0.30000 0.60000"/>
        </geometry>
        </visual>
    </link>

    <link name="left_back_wheel_link">
        <collision name="left_back_wheel_collision">
        <origin rpy="-0.00000 0.00000 -0.00000" xyz="0.00000 0.00000 0.00000"/>
        <geometry>
            <mesh filename="file://$(find robot_model_description)/meshes/dae/Cylinder.023.dae" scale="0.75000 0.75000 0.12500"/>
        </geometry>
        <surface>
        <friction>
            <ode>
            <mu>1.0</mu>
            <mu2>1.0</mu2>
            </ode>
        </friction>
        </surface>
        </collision>
        <inertial>
        <inertia ixx="2.72757" ixy="0.00000" ixz="0.00000" iyy="1.41267" iyz="0.00000" izz="1.41267"/>
        <origin rpy="0.00000 0.00000 0.00000" xyz="0.00000 0.00000 -0.02068"/>
        <mass value="10.00000"/>
        </inertial>
        <visual name="left_back_wheel">
        <origin rpy="-0.00000 0.00000 -0.00000" xyz="0.00000 0.00000 0.00000"/>
        <material name="Material.001"/>
        <geometry>
            <mesh filename="file://$(find robot_model_description)/meshes/dae/Cylinder.023.dae" scale="0.75000 0.75000 0.12500"/>
        </geometry>
        </visual>
    </link>

    <link name="left_front_sop_link">
        <collision name="left_front_sop_collision">
        <origin rpy="0.00000 0.00000 -0.00000" xyz="0.00000 0.00000 -0.00000"/>
        <geometry>
            <box size="0.60000 0.30000 0.60000"/>
        </geometry>
        </collision>
        <inertial>
        <inertia ixx="0.18750" ixy="0.00000" ixz="0.00000" iyy="0.30000" iyz="0.00000" izz="0.18750"/>
        <origin rpy="0.00000 0.00000 0.00000" xyz="0.00000 0.00000 -0.00000"/>
        <mass value="5.00000"/>
        </inertial>
        <visual name="left_front_sop">
        <origin rpy="0.00000 0.00000 -0.00000" xyz="0.00000 0.00000 -0.00000"/>
        <material name="turnarrow.004"/>
        <geometry>
            <box size="0.60000 0.30000 0.60000"/>
        </geometry>
        </visual>
    </link>

    <link name="left_front_wheel_link">
        <collision name="left_front_wheel_collision">
        <origin rpy="-0.00000 0.00000 -0.00000" xyz="-0.00000 0.00000 0.00000"/>
        <geometry>
            <mesh filename="file://$(find robot_model_description)/meshes/dae/Cylinder.021.dae" scale="0.75000 0.75000 0.12500"/>
        </geometry>
        <surface>
        <friction>
            <ode>
            <mu>1.0</mu>
            <mu2>1.0</mu2>
            </ode>
        </friction>
        </surface>
        </collision>
        <inertial>
        <inertia ixx="2.72188" ixy="0.00000" ixz="0.00000" iyy="1.41049" iyz="0.00000" izz="1.41049"/>
        <origin rpy="0.00000 0.00000 0.00000" xyz="-0.00000 0.00000 -0.02178"/>
        <mass value="10.00000"/>
        </inertial>
        <visual name="left_front_wheel">
        <origin rpy="-0.00000 0.00000 -0.00000" xyz="-0.00000 0.00000 0.00000"/>
        <material name="Material.001"/>
        <geometry>
            <mesh filename="file://$(find robot_model_description)/meshes/dae/Cylinder.021.dae" scale="0.75000 0.75000 0.12500"/>
        </geometry>
        </visual>
    </link>

    <link name="right_back_sop_link">
        <collision name="right_back_sop_collision">
        <origin rpy="0.00000 0.00000 -0.00000" xyz="0.00000 0.00000 -0.00000"/>
        <geometry>
            <box size="0.60000 0.30000 0.60000"/>
        </geometry>
        </collision>
        <inertial>
        <inertia ixx="0.18750" ixy="0.00000" ixz="0.00000" iyy="0.30000" iyz="0.00000" izz="0.18750"/>
        <origin rpy="0.00000 0.00000 0.00000" xyz="-0.00000 -0.00000 -0.00000"/>
        <mass value="5.00000"/>
        </inertial>
        <visual name="right_back_sop">
        <origin rpy="0.00000 0.00000 -0.00000" xyz="0.00000 0.00000 -0.00000"/>
        <material name="turnarrow.004"/>
        <geometry>
            <box size="0.60000 0.30000 0.60000"/>
        </geometry>
        </visual>
    </link>

    <link name="right_back_wheel_link">
        <collision name="right_back_wheel_collision">
        <origin rpy="3.14159 0.00000 3.14159" xyz="0.00000 0.00000 -0.00000"/>
        <geometry>
            <mesh filename="file://$(find robot_model_description)/meshes/dae/Cylinder.025.dae" scale="0.75000 0.75000 0.12500"/>
        </geometry>
        <surface>
        <friction>
            <ode>
            <mu>1.0</mu>
            <mu2>1.0</mu2>
            </ode>
        </friction>
        </surface>
        </collision>
        <inertial>
        <inertia ixx="2.72757" ixy="0.00000" ixz="0.00000" iyy="1.41267" iyz="0.00000" izz="1.41267"/>
        <origin rpy="0.00000 0.00000 0.00000" xyz="0.00000 -0.00000 -0.02068"/>
        <mass value="10.00000"/>
        </inertial>
        <visual name="right_back_wheel">
        <origin rpy="3.14159 0.00000 3.14159" xyz="0.00000 0.00000 -0.00000"/>
        <material name="Material.001"/>
        <geometry>
            <mesh filename="file://$(find robot_model_description)/meshes/dae/Cylinder.025.dae" scale="0.75000 0.75000 0.12500"/>
        </geometry>
        </visual>
    </link>

    <link name="right_front_sop_link">
        <collision name="right_front_sop_collision">
        <origin rpy="0.00000 0.00000 -0.00000" xyz="0.00000 0.00000 -0.00000"/>
        <geometry>
            <box size="0.60000 0.30000 0.60000"/>
        </geometry>
        </collision>
        <inertial>
        <inertia ixx="0.18750" ixy="0.00000" ixz="0.00000" iyy="0.30000" iyz="0.00000" izz="0.18750"/>
        <origin rpy="0.00000 0.00000 0.00000" xyz="0.00000 0.00000 -0.00000"/>
        <mass value="5.00000"/>
        </inertial>
        <visual name="right_front_sop">
        <origin rpy="0.00000 0.00000 -0.00000" xyz="0.00000 0.00000 -0.00000"/>
        <material name="turnarrow.004"/>
        <geometry>
            <box size="0.60000 0.30000 0.60000"/>
        </geometry>
        </visual>
    </link>
    
    <link name="right_front_wheel_link">
        <collision name="right_front_wheel_collision">
        <origin rpy="3.14159 0.00000 3.14159" xyz="0.00000 0.00000 0.00000"/>
        <geometry>
            <mesh filename="file://$(find robot_model_description)/meshes/dae/Cylinder.027.dae" scale="0.75000 0.75000 0.12500"/>
        </geometry>
        <surface>
        <friction>
            <ode>
            <mu>1.0</mu>
            <mu2>1.0</mu2>
            </ode>
        </friction>
        </surface>
        </collision>
        <inertial>
        <inertia ixx="2.72757" ixy="0.00000" ixz="0.00000" iyy="1.41267" iyz="0.00000" izz="1.41267"/>
        <origin rpy="0.00000 0.00000 0.00000" xyz="0.00000 -0.00000 0.02068"/>
        <mass value="10.00000"/>
        </inertial>
        <visual name="right_front_wheel">
        <origin rpy="3.14159 0.00000 3.14159" xyz="0.00000 0.00000 0.00000"/>
        <material name="Material.001"/>
        <geometry>
            <mesh filename="file://$(find robot_model_description)/meshes/dae/Cylinder.027.dae" scale="0.75000 0.75000 0.12500"/>
        </geometry>
        </visual>
    </link>    

    <!-- Transmission for left back wheel -->
    <transmission name="left_back_wheel_joint_link">
    <type>transmission_interface/SimpleTransmission</type>
    <joint name="left_back_wheel_link_joint">
        <hardwareInterface>hardware_interface/VelocityJointInterface</hardwareInterface>
    </joint>
    <actuator name="left_back_wheel_motor">
        <mechanicalReduction>1</mechanicalReduction>
    </actuator>
    </transmission>

    <!-- Transmission for left front wheel -->
    <transmission name="left_front_wheel_joint_link">
    <type>transmission_interface/SimpleTransmission</type>
    <joint name="left_front_wheel_link_joint">
        <hardwareInterface>hardware_interface/VelocityJointInterface</hardwareInterface>
    </joint>
    <actuator name="left_front_wheel_motor">
        <mechanicalReduction>1</mechanicalReduction>
    </actuator>
    </transmission>

    <!-- Transmission for right back wheel -->
    <transmission name="right_back_wheel_joint_link">
    <type>transmission_interface/SimpleTransmission</type>
    <joint name="right_back_wheel_link_joint">
        <hardwareInterface>hardware_interface/VelocityJointInterface</hardwareInterface>
    </joint>
    <actuator name="right_back_wheel_motor">
        <mechanicalReduction>1</mechanicalReduction>
    </actuator>
    </transmission>

    <!-- Transmission for right front wheel -->
    <transmission name="right_front_wheel_joint_link">
    <type>transmission_interface/SimpleTransmission</type>
    <joint name="right_front_wheel_link_joint">
        <hardwareInterface>hardware_interface/VelocityJointInterface</hardwareInterface>
    </joint>
    <actuator name="right_front_wheel_motor">
        <mechanicalReduction>1</mechanicalReduction>
    </actuator>
    </transmission>

    <gazebo reference="left_back_wheel_link">
    <mu1>5</mu1>
    <mu2>5</mu2>
    <!--<kp>2.75e6</kp>
    <kd>8.25e1</kd>
    <fdir1>0 0 0</fdir1>
    <maxContacts>4</maxContacts>-->
    </gazebo>

    <gazebo reference="left_front_wheel_link">
    <mu1>5</mu1>
    <mu2>5</mu2>
    <!--<kp>2.75e6</kp>
    <kd>8.25e1</kd>
    <fdir1>0 0 0</fdir1>
    <maxContacts>4</maxContacts>-->
    </gazebo>

    <gazebo reference="right_back_wheel_link">
    <mu1>5</mu1>
    <mu2>5</mu2>
    <!--<kp>2.75e6</kp>
    <kd>8.25e1</kd>
    <fdir1>0 0 0</fdir1>
    <maxContacts>4</maxContacts>-->
    </gazebo>

    <gazebo reference="right_front_wheel_link">
    <mu1>5</mu1>
    <mu2>5</mu2>
    <!--<kp>2.75e6</kp>
    <kd>8.25e1</kd>
    <fdir1>0 0 0</fdir1>
    <maxContacts>4</maxContacts>-->
    </gazebo>

  </xacro:macro>
</robot>